Traceback (most recent call last):
  File "/nb/server.py", line 48, in StationMax
    respone = self.session.execute(self.max_statement, [request.station])
  File "cassandra/cluster.py", line 2637, in cassandra.cluster.Session.execute
  File "cassandra/cluster.py", line 4920, in cassandra.cluster.ResponseFuture.result
cassandra.Unavailable: Error from server: code=1000 [Unavailable exception] message="Cannot achieve consistency level ALL" info={'consistency': 'ALL', 'required_replicas': 3, 'alive_replicas': 2}

During handling of the above exception, another exception occurred:

Traceback (most recent call last):
  File "/usr/local/lib/python3.10/dist-packages/grpc/_server.py", line 552, in _call_behavior
    response_or_iterator = behavior(argument, context)
  File "/nb/server.py", line 55, in StationMax
    return station_pb2.StationMaxResponse(tmax=0,error=error_message)
AttributeError: module 'station_pb2' has no attribute 'StationMaxResponse'
